[2023-11-14T11:19:59.158+0000] {taskinstance.py:1083} INFO - Dependencies all met for <TaskInstance: transform_dag.transform_task manual__2023-11-14T11:19:56.388583+00:00 [queued]>
[2023-11-14T11:19:59.163+0000] {taskinstance.py:1083} INFO - Dependencies all met for <TaskInstance: transform_dag.transform_task manual__2023-11-14T11:19:56.388583+00:00 [queued]>
[2023-11-14T11:19:59.163+0000] {taskinstance.py:1279} INFO - 
--------------------------------------------------------------------------------
[2023-11-14T11:19:59.163+0000] {taskinstance.py:1280} INFO - Starting attempt 1 of 1
[2023-11-14T11:19:59.163+0000] {taskinstance.py:1281} INFO - 
--------------------------------------------------------------------------------
[2023-11-14T11:19:59.211+0000] {taskinstance.py:1300} INFO - Executing <Task(PythonOperator): transform_task> on 2023-11-14 11:19:56.388583+00:00
[2023-11-14T11:19:59.215+0000] {standard_task_runner.py:55} INFO - Started process 22121 to run task
[2023-11-14T11:19:59.218+0000] {standard_task_runner.py:82} INFO - Running: ['airflow', 'tasks', 'run', 'transform_dag', 'transform_task', 'manual__2023-11-14T11:19:56.388583+00:00', '--job-id', '8', '--raw', '--subdir', 'DAGS_FOLDER/transform_dag.py', '--cfg-path', '/tmp/tmpu9dr_wjh']
[2023-11-14T11:19:59.219+0000] {standard_task_runner.py:83} INFO - Job 8: Subtask transform_task
[2023-11-14T11:19:59.292+0000] {task_command.py:388} INFO - Running <TaskInstance: transform_dag.transform_task manual__2023-11-14T11:19:56.388583+00:00 [running]> on host codespaces-1a8ad4
[2023-11-14T11:19:59.528+0000] {taskinstance.py:1507} INFO - Exporting the following env vars:
AIRFLOW_CTX_DAG_OWNER=airflow
AIRFLOW_CTX_DAG_ID=transform_dag
AIRFLOW_CTX_TASK_ID=transform_task
AIRFLOW_CTX_EXECUTION_DATE=2023-11-14T11:19:56.388583+00:00
AIRFLOW_CTX_TRY_NUMBER=1
AIRFLOW_CTX_DAG_RUN_ID=manual__2023-11-14T11:19:56.388583+00:00
[2023-11-14T11:19:59.530+0000] {taskinstance.py:1768} ERROR - Task failed with exception
Traceback (most recent call last):
  File "/usr/local/python/3.10.8/lib/python3.10/site-packages/airflow/operators/python.py", line 175, in execute
    return_value = self.execute_callable()
  File "/usr/local/python/3.10.8/lib/python3.10/site-packages/airflow/operators/python.py", line 192, in execute_callable
    return self.python_callable(*self.op_args, **self.op_kwargs)
  File "/workspaces/hands-on-introduction-data-engineering-4395021/airflow/dags/transform_dag.py", line 17, in transform_data
    df = pd.read_csv('/workspaces/workspaces/hands-on-introduction-data-engineering-4395021/lab/orchestrated/airflow-extract-data.csv')
  File "/home/codespace/.local/lib/python3.10/site-packages/pandas/io/parsers/readers.py", line 948, in read_csv
    return _read(filepath_or_buffer, kwds)
  File "/home/codespace/.local/lib/python3.10/site-packages/pandas/io/parsers/readers.py", line 611, in _read
    parser = TextFileReader(filepath_or_buffer, **kwds)
  File "/home/codespace/.local/lib/python3.10/site-packages/pandas/io/parsers/readers.py", line 1448, in __init__
    self._engine = self._make_engine(f, self.engine)
  File "/home/codespace/.local/lib/python3.10/site-packages/pandas/io/parsers/readers.py", line 1705, in _make_engine
    self.handles = get_handle(
  File "/home/codespace/.local/lib/python3.10/site-packages/pandas/io/common.py", line 863, in get_handle
    handle = open(
FileNotFoundError: [Errno 2] No such file or directory: '/workspaces/workspaces/hands-on-introduction-data-engineering-4395021/lab/orchestrated/airflow-extract-data.csv'
[2023-11-14T11:19:59.533+0000] {taskinstance.py:1318} INFO - Marking task as FAILED. dag_id=transform_dag, task_id=transform_task, execution_date=20231114T111956, start_date=20231114T111959, end_date=20231114T111959
[2023-11-14T11:19:59.581+0000] {standard_task_runner.py:100} ERROR - Failed to execute job 8 for task transform_task ([Errno 2] No such file or directory: '/workspaces/workspaces/hands-on-introduction-data-engineering-4395021/lab/orchestrated/airflow-extract-data.csv'; 22121)
[2023-11-14T11:19:59.597+0000] {local_task_job.py:208} INFO - Task exited with return code 1
[2023-11-14T11:19:59.607+0000] {taskinstance.py:2578} INFO - 0 downstream tasks scheduled from follow-on schedule check
